Workbook

Sheet Sheet1
A1: sentiment | B1: target_person | C1: target_party | D1: favorability | E1: topic | F1: location | G1: dtname | H1: latitude | I1: longitude | J1: emotion | K1: text
A2: neutral | B2: Ramesh Peruvazhudi | C2: NTK | D2: neutral | E2: nomination filing / candidate nomination | F2: Kallakurichi, Tamil Nadu | G2: Kallakurichi | H2: 11.738 | I2: 78.964 | J2: neutral | K2: Kallakurichi, Tamil Nadu: Naam Tamilar Katchi candidate Ramesh Peruvazhudi filed his nomination for the Sankarapuram Assembly constituency on the first day of nomination filing for the upcoming Tamil Nadu elections. He reached the election office in a procession from https://t.co/H7AlpTKkTr
A3: positive | B3: Jayasudha Lakshmi Kandan | C3: AIADMK | D3: positive | E3: candidate announcement / celebration | F3: Arani, Tamil Nadu | G3: Arani | H3: 12.6677 | I3: 79.2833 | J3: celebratory | K3: Arani, Tamil Nadu: AIADMK cadres celebrated the announcement of Jayasudha Lakshmi Kandan as the party’s candidate for the Arani Assembly constituency in the 2026 elections by bursting crackers and distributing sweets. https://t.co/GTuz8lI5mT
A4: positive | B4: Vijay | C4: TVK | D4: positive | E4: candidate selection / emotional moment | F4: Tamil Nadu | G4: General | J4: emotional | K4: Tamil Nadu Election: Vijay Gives Driver's Son Poll Ticket, Emotional Moment On Stage Goes Viral #TNPolls #Elections #TamilNadu #TVK #Vijay https://t.co/zmL1PrV6sh
A5: neutral | B5: Vijay | C5: TVK | D5: neutral | E5: political competition / three-cornered contest | F5: Chennai | G5: General | J5: curious | K5: #Janadesh | Can Vijay’s entry into Tamil Nadu politics turn the traditional DMK vs AIADMK contest into a three-cornered fight in the 2026 Assembly elections? Correspondent @Akshayanath reports from Chennai. Watch The Full Program: https://t.co/f2AgOehxv5 #TamilNaduElections https://t.co/y75KwPascT
A6: neutral | B6: Party | C6: Information / General Updates | D6: neutral | E6: election schedule / polling hours | F6: Tamil Nadu | G6: General | J6: neutral | K6: Appointment of dates for various stages of elections and fixation of polling hours for all Assembly constituencies in Tamil Nadu https://t.co/EKA16NFcPl
A7: positive | B7: Arun Nehru | C7: DMK | D7: positive | E7: party manifesto / policy | F7: Tiruchirappalli, Tamil Nadu | G7: Tiruchirappalli | H7: 10.7905 | I7: 78.7047 | J7: optimistic | K7: #WATCH | Tiruchirappalli | On release of the party manifesto for Tamil Nadu elections, DMK MP Arun Nehru says," You should see the progressive nature of the manifesto. It is flexible and adaptable to every kind of person..." https://t.co/coNTHJjus2
A8: positive | B8: Arun Nehru | C8: DMK | D8: positive | E8: party manifesto / policy | F8: Chennai, Tamil Nadu | G8: Chennai | H8: 13.0827 | I8: 80.2707 | J8: optimistic | K8: #WATCH | Chennai | On release of the party manifesto for Tamil Nadu elections, DMK MP Arun Nehru says," You should see the progressive nature of the manifesto. It is flexible and adaptable to every kind of person..." https://t.co/IlF2mIbJmk
A9: neutral | B9: Vijay | C9: TVK | D9: neutral | E9: campaigning / roadshow | F9: Chennai, Tamil Nadu | G9: Chennai | H9: 13.0827 | I9: 80.2707 | J9: energetic | K9: #WATCH | Tamil Nadu Elections 2026 | Chennai: TVK chief and actor Vijay conducts a roadshow. He is contesting the State Assembly elections from the Perambur and Trichy East constituencies. #tvk #TVKVijay‌ #TVKVijay‌HQ #chennai #vijay https://t.co/TGebvRq4ir
A10: neutral | B10: M. K. Stalin | C10: DMK | D10: neutral | E10: Tamil Nadu Assembly elections / nomination | F10: Kolathur, Tamil Nadu | G10: Kolathur | H10: 13.121 | I10: 80.215 | J10: neutral | K10: MK Stalin Files Nomination from Kolathur, Aims for Fourth Straight Win in Tamil Nadu Elections https://t.co/j2fziZEd9N https://t.co/HExw9slHt7
A11: neutral | B11: M. K. Stalin | C11: DMK | D11: neutral | E11: Tamil Nadu Assembly elections / nomination | F11: Kolathur, Tamil Nadu | G11: Kolathur | H11: 13.121 | I11: 80.215 | J11: neutral | K11: With the nomination process for the Tamil Nadu Assembly elections formally underway, Chief Minister M. K. Stalin on Monday filed his nomination from the Kolathur constituency, where he is seeking a fourth consecutive term. #OmmcomNews https://t.co/PqfmODiLkO
A12: positive | B12: M. K. Stalin | C12: DMK | D12: positive | E12: election campaign / voter support | F12: Tamil Nadu | G12: General | J12: optimism | K12: #Exclusive | "Have contested elections more than three times, and I'm seeing greater support the fourth time": Tamil Nadu CM MK Stalin #BattleForTamilNadu #TamilNaduPolitics #AssemblyPolls https://t.co/rUAXBPWLTA
A13: neutral | B13: Vijay | C13: TVK | D13: neutral | E13: campaign / roadshow | F13: Chennai | G13: General | J13: neutral | K13: #WATCH | Tamil Nadu Elections 2026 | Chennai: TVK chief and actor Vijay conducts a roadshow. He is contesting the State Assembly elections from the Perambur and Trichy East constituencies. (Video Source: TVK) https://t.co/Xrd1rHdenz
A14: neutral | B14: Vijay | C14: TVK | D14: neutral | E14: campaign / roadshow | F14: Chennai | G14: General | J14: neutral | K14: #WATCH | Tamil Nadu Elections 2026 | Chennai: TVK chief and actor Vijay conducts a roadshow. He is contesting the State Assembly elections from the Perambur and Trichy East constituencies. (Video Source: TVK) https://t.co/Xrd1rHdenz
A15: negative | B15: Suryakant | D15: negative | E15: elections / internet disruption | F15: Tamil Nadu | G15: General | J15: sarcasm | K15: @Aunindyo2023 Sporadic 3G till a month before US midterms after Tamil Nadu elections? Suryakant will also relish it.
A16: neutral | B16: Party | C16: DMK | D16: neutral | E16: candidate list / elections | F16: Tamil Nadu | G16: General | J16: neutral | K16: 🗳️ Tamil Nadu Assembly Elections 2026 Update Dravida Munnetra Kazhagam (DMK) ने 2026 विधानसभा चुनाव के लिए अपने उम्मीदवारों की पूरी सूची जारी कर दी है। 📅 मतदान: 23 अप्रैल 2026 #TamilNaduElections2026 #DMK #MKStalin #UdhayanidhiStalin #MissyNEWSDECODE https://t.co/bAJlT0frmj
A17: positive | B17: M. K. Stalin | C17: DMK | D17: positive | E17: nomination / election roadmap | F17: Kolathur, Chennai, Tamil Nadu | G17: Kolathur | H17: 13.121 | I17: 80.215 | J17: optimism | K17: Tamil Nadu politics update 🇮🇳 M. K. Stalin ne Chennai ke Kolathur se 23 April ko hone wale Tamil Nadu Assembly elections ke liye nomination file kar diya। “game-changing” roadmap hai. #TamilNadu #MKStalin #DMK #Election2026 #TamilNaduPolitics #MissyNEWSDECODE https://t.co/WAUycifyJD
A18: neutral | B18: Party | D18: neutral | E18: Home voting / General Elections 2026 | F18: Assam, Kerala, Puducherry, Tamil Nadu, West Bengal | G18: General | J18: neutral | K18: General Elections to Legislative Assemblies of Assam , Kerala, Puducherry, Tamil Nadu and West Bengal and bye-elections in 6 states 2026: Over 2.3 lakh Electors to avail the Home Voting Read more : https://t.co/GxJe7rDgqo… https://t.co/mabYGuvuup
A19: positive | B19: Kanimozhi N. V. N. Somu | C19: DMK | D19: positive | E19: Election nominations / predicted victory | F19: Chennai, Tamil Nadu | G19: Chennai | H19: 13.0827 | I19: 80.2707 | J19: confident | K19: Chennai Tamil Nadu: DMK MP Kanimozhi N. V. N. Somu says, ''DMK didn't get geared up for elections today. It's our leader who's going to have a landslide victory of 200 constituencies have filed the nomination today on the starting of the first day. That is something which we are https://t.co/lWTfvKmA6I
A20: positive | B20: M.K. Stalin | C20: DMK | D20: positive | E20: Nomination filing / Assembly elections | F20: Kolathur, Tamil Nadu | G20: Kolathur | H20: 13.121 | I20: 80.215 | J20: confident | K20: ‘Victory Margin Will be Very Big This Time’: CM Stalin Files Nomination From Kolathur Constituency For Tamil Nadu Assembly elections https://t.co/qjCSts8n1l https://t.co/s21bjbFPsR
A21: positive | B21: M.K. Stalin | C21: DMK (alliance) | D21: positive | E21: Alliance readiness for Assembly elections | F21: Chennai, Tamil Nadu | G21: Chennai | H21: 13.0827 | I21: 80.2707 | J21: confident | K21: Chennai, Tamil Nadu: DMK President and Chief Minister M.K. Stalin said the Secular Progressive Alliance is fully prepared for the upcoming Assembly elections, following a meeting at Anna Arivalayam. He noted that the alliance is long-standing and has contested multiple elections https://t.co/C86BITRvft
A22: positive | B22: M. Sudhakaran | C22: TVK | D22: positive | E22: Campaign rally / public procession | F22: Ulundurpet, Tamil Nadu | G22: Ulundurpet | H22: =VLOOKUP(G22,Sheet4!A:C,2,0) -> 11.6932 | I22: =VLOOKUP(G22,Sheet4!A:C,3,0) -> 79.287 | J22: celebratory | K22: Ulundurpet, Tamil Nadu: Tamilaga Vettri Kazhagam (TVK) candidate M. Sudhakaran received a grand welcome in the Ulundurpet constituency ahead of the Assembly elections. Arriving from Chennai, he was greeted by thousands of supporters in a large procession from the toll plaza to https://t.co/mtx5dAoVkD
A23: neutral | B23: T.S. Vakeel Ahmed | C23: DMK++ | D23: neutral | E23: Alliance support / demands (prisoner release, reservation) | F23: Tamil Nadu | G23: General | J23: neutral | K23: @ndmehta19 @TelanganaMaata @Mahaveer_VJ Yes, the claim is true. AIMIM Tamil Nadu unit leaders (State President T.S. Vakeel Ahmed and team) met CM M.K. Stalin yesterday and extended support to the DMK-Congress alliance for the 2026 assembly elections. They raised two demands: release of Muslim prisoners and 7%
A24: positive | B24: Rakesh | C24: TVK | D24: positive | E24: Candidate confidence / upcoming election | F24: Harur (SC), Dharmapuri, Tamil Nadu | G24: Dharmapuri | H24: =VLOOKUP(G24,Sheet4!A:C,2,0) -> 12.1277 | I24: =VLOOKUP(G24,Sheet4!A:C,3,0) -> 78.1579 | J24: confident | K24: Dharmapuri, Tamil Nadu: TVK candidate Rakesh, contesting from the Harur (SC) Assembly constituency, expressed confidence of a decisive victory in the upcoming elections. In an interview, he said previous representatives failed to fulfill development promises and assured that, if https://t.co/4PYKSsdI5p
A25: neutral | B25: Vijay | C25: TVK | D25: neutral | E25: Battleground constituency / election contest (Perambur) | F25: Perambur, North Chennai, Tamil Nadu | G25: Perambur | H25: 13.0827 | I25: 80.2707 | J25: anticipatory | K25: South Central | The Perambur constituency has become the battleground seat of the 2026 Tamil Nadu elections. With the actor-turned-politician Vijay contesting from this seat, all eyes remain on this working-class hub in North Chennai Watch this special on-ground report by https://t.co/5CVGLNZxHN
A26: neutral | B26: Vijay | C26: TVK | D26: neutral | E26: asset declaration / poll affidavit | F26: Tamil Nadu | G26: General | J26: informative | K26: Tamil Nadu Assembly Elections: TVK Chief Vijay Declares Rs 520 Crore Assets In Poll Affidavit #TamilNaduAssemblyElections https://t.co/ftLxdzIIYK
A27: neutral | B27: Vijay | C27: TVK | D27: neutral | E27: candidate announcements / nominations | F27: Tamil Nadu | G27: General | J27: emotional | K27: Actor and 'Tamizhaga Vettri Kazhagam' chief Vijay announced his candidates for the 234 assembly seats ahead of the upcoming elections in Tamil Nadu. Among these candidates was Sabarinathan, the son of his former driver and current PA, Rajendran. As both father and son welled up https://t.co/59A2pWI6L3
A28: neutral | B28: Udhayanidhi Stalin | C28: DMK | D28: neutral | E28: campaigning for candidate | F28: Kanchipuram, Tamil Nadu | G28: Kanchipuram | H28: =VLOOKUP(G28,Sheet4!A:C,2,0) -> 12.8342 | I28: =VLOOKUP(G28,Sheet4!A:C,3,0) -> 79.7036 | J28: informative | K28: VIDEO | Kanchipuram: Tamil Nadu Deputy Chief Minister Udhayanidhi Stalin campaigns for DMK candidate Nithya Sugumar ahead of the upcoming state legislative assembly elections scheduled for April 23. (Full video available on PTI Videos - https://t.co/n147TvrpG7) https://t.co/zHVgCnVjcZ
A29: positive | B29: Party | D29: neutral | E29: elections (humorous commentary) | F29: Bangalore / Tamil Nadu | G29: General | J29: amused | K29: Yesterday was at the Def Leppard concert in Bangalore where the warm up act was "Thermal and a Quarter". In Tamil Nadu elections the warm up act is "Biryani and a quarter" 😀
A30: neutral | B30: Party | D30: neutral | E30: personal branding in state elections | F30: West Bengal; Tamil Nadu; Assam; Kerala | G30: General | J30: informative | K30: New face of governance: How personal branding is reshaping state elections In the election-bound states West Bengal, Tamil Nadu, Assam and Kerala, the image built around the incumbents looms large ✍️ @pratulsharmaa Read: https://t.co/oG1rQ0V82Y (Indian politics, personal
A31: neutral | B31: Vijay | C31: TVK | D31: neutral | E31: entry into politics / candidate selection | F31: Tamil Nadu | G31: General | J31: controversial | K31: Vijay, popularly known as “Thalapathy” (meaning leader), has stepped into active politics with his party. For the 2026 Tamil Nadu Assembly elections, he announced his list of candidates, one of whom is the son of his former driver. The decision has sparked widespread discussion, https://t.co/bVaXIBP9Lo
A32: negative | B32: Vijay | C32: TVK | D32: unfavorable | E32: opposition campaigning / contested seat (Perambur) | F32: Perambur, Tamil Nadu | G32: Perambur | H32: =VLOOKUP(G32,Sheet4!A:C,2,0) -> 13.1186 | I32: =VLOOKUP(G32,Sheet4!A:C,3,0) -> 80.2337 | J32: oppositional | K32: Tamil Nadu Election: Perambur Heats Up Early As Famous Actress Campaigns Against Vijay #TNPolls #elections #tamilnadu #TVK #Vijay https://t.co/v17KCTmyry
A33: neutral | B33: Party | C33: AIADMK++ | D33: neutral | E33: release of final candidate list | F33: Tamil Nadu | G33: General | J33: informative | K33: Tamil Nadu elections 2026: PMK releases final list of candidates | Check here https://t.co/ibngB58VpR #inqalabNews #india https://t.co/fMhAzqeOHk
A34: neutral | B34: M. K. Stalin | C34: DMK | D34: neutral | E34: Tamil Nadu Assembly Elections | F34: Kolathur, Chennai, Tamil Nadu | G34: Kolathur | H34: 13.121 | I34: 80.215 | J34: neutral | K34: 🎥 | WATCH | Tamil Nadu CM M. K. Stalin filed his nomination as DMK candidate from the Kolathur constituency in Chennai for the Assembly elections. @mkstalin #MKStalin #DMK #TamilNaduElections #Chennai #Kolathur #IndianPolitics #TheStatesman https://t.co/4yAzz4rrhm
A35: neutral | B35: Vijay | C35: TVK | D35: neutral | E35: Tamil Nadu Assembly Elections | F35: Perambur and Trichy East, Tamil Nadu | G35: Tiruchirappalli | H35: =VLOOKUP(G35,Sheet4!A:C,2,0) -> 10.7905 | I35: =VLOOKUP(G35,Sheet4!A:C,3,0) -> 78.7047 | J35: neutral | K35: నామినేషన్ వేసిన టీవీకే అధినేత విజయ్..పెరంబూర్, తిరుచ్చి ఈస్ట్ నుండి పోటీ! Vijay Contests From Perambur &amp; Trichy East, Files Nomination | Tamil Nadu Elections 2026 #TVKVijay‌ #vijaythalapathy #TVK‌ #perambur #TrichyEast #TamilNaduElections #tamilnadu #LatestNews #BreakingNews https://t.co/OauHNaqFcJ
A36: positive | B36: Vijay | C36: TVK | D36: positive | E36: Tamil Nadu Assembly Elections | F36: Perambur, Tamil Nadu | G36: Perambur | H36: =VLOOKUP(G36,Sheet4!A:C,2,0) -> 13.1186 | I36: =VLOOKUP(G36,Sheet4!A:C,3,0) -> 80.2337 | J36: hopeful | K36: Actor-turned-politician Vijay Monday filed his nomination papers from the Perambur Assembly constituency, marking a significant milestone in his political journey ahead of the Tamil Nadu Assembly elections. #Vijay #Nomination #Perambur #Politics #TamilNadu #OrissaPOST 📲 https://t.co/PUnWDRLX27
A37: neutral | B37: Vijay | C37: TVK | D37: neutral | E37: Tamil Nadu Assembly Elections | F37: Perambur and Trichy East; Chennai, Tamil Nadu | G37: Tiruchirappalli | H37: 13.0827 | I37: 80.2707 | J37: neutral | K37: #WATCH | Tamil Nadu Elections 2026 | Chennai: TVK chief Vijay conducts a roadshow after filing his nomination. He is contesting the State Assembly elections from Perambur and Trichy East constituencies. (Video Source: TVK) https://t.co/RqYdKDuVlc
A38: neutral | B38: M. K. Stalin | C38: DMK | D38: neutral | E38: Tamil Nadu Assembly Elections | F38: Kolathur, Chennai, Tamil Nadu | G38: Kolathur | H38: 13.121 | I38: 80.215 | J38: neutral | K38: Tamil Nadu Assembly Elections | Chennai: Tamil Nadu CM MK Stalin files his nomination as DMK candidate from Kolathur constituency. https://t.co/vbZKAXDBbE
A39: neutral | B39: M. K. Stalin | C39: DMK | D39: neutral | E39: Tamil Nadu Assembly Elections | F39: Kolathur; Perambur; Trichy East, Tamil Nadu | G39: Tiruchirappalli | H39: =VLOOKUP(G39,Sheet4!A:C,2,0) -> 10.7905 | I39: =VLOOKUP(G39,Sheet4!A:C,3,0) -> 78.7047 | J39: neutral | K39: ತಮಿಳುನಾಡು ಚುನಾವಣೆ: ಕೊಳತ್ತೂರಿನಿಂದ ನಾಮಪತ್ರ ಸಲ್ಲಿಸಿದ ಸಿಎಂ ಎಂ.ಕೆ.ಸ್ಟಾಲಿನ್; ನಟ ವಿಜಯ್ ಸಹ ಚುನವಣಾ ಪ್ರವೇಶ | Tamil Nadu elections https://t.co/uyEK4jyJGH #TamilNaduelections #CMMKStalin #filesnomination #Kolathur #ActorVijay #Vijayavani #KannadaNews
A40: positive | B40: Vijay | C40: TVK | D40: positive | E40: Tamil Nadu Assembly Elections | F40: Perambur and Trichy East; Kolathur, Tamil Nadu | G40: Tiruchirappalli | H40: =VLOOKUP(G40,Sheet4!A:C,2,0) -> 10.7905 | I40: =VLOOKUP(G40,Sheet4!A:C,3,0) -> 78.7047 | J40: excited | K40: 🔴 ELECTIONS 2026 🗳️ Tamil Nadu Elections హాట్! Vijay Perambur &amp; Trichy East నుండి Contest చేస్తున్నారు CM Stalin Kolathur నుండి Nomination దాఖలు చేశారు ✅ #ForTeluguNews #TamilNaduElections2026 #Vijay #tamil
...

Sheet Sheet2
A1: Tamil Nadu | B1: False
A2: Chennai | B2: True
A3: Perambur | B3: True
A4: Kolathur | B4: True
A5: Trichy East | B5: True
A6: Tiruchirappalli | B6: True
A7: Madurai | B7: True
A8: Coimbatore | B8: True
A9: Kanchipuram | B9: True
A10: Chengalpattu | B10: True
A11: Tambaram | B11: True
A12: Tiruvarur | B12: True
... A86: Nepal | B86: False

Sheet Sheet3
A1: Location
A2: Kallakurichi
A3: Arani
A4: Tiruchirappalli
A5: Chennai
A6: Kolathur
A7: Ulundurpet
A8: Dharmapuri
A9: Perambur
A10: Kanchipuram
A11: Madurai
A12: Chengalpattu
... A124: Telugu-speaking region

Sheet Sheet4
A1: Location | B1: Latitude | C1: Longitude
A2: Kallakurichi | B2: 11.7381 | C2: 78.9629
A3: Arani | B3: 12.6683 | C3: 79.2857
A4: Tiruchirappalli | B4: 10.7905 | C4: 78.7047
A5: Chennai | B5: 13.0827 | C5: 80.2707
A6: Kolathur | B6: 13.1245 | C6: 80.215
A7: Ulundurpet | B7: 11.6932 | C7: 79.287
A8: Dharmapuri | B8: 12.1277 | C8: 78.1579
A9: Perambur | B9: 13.1186 | C9: 80.2337
A10: Kanchipuram | B10: 12.8342 | C10: 79.7036
A11: Madurai | B11: 9.9252 | C11: 78.1198
A12: Chengalpattu | B12: 12.6819 | C12: 79.9888
A13: Tamil | B13: FALSE | C13: FALSE
A14: Tiruvarur | B14: 10.7725 | C14: 79.6368
A15: Tamil Nadu | B15: FALSE | C15: FALSE
A16: Tiruchuli | B16: 9.4833 | C16: 78.1333
A17: Kumbakonam | B17: 10.9617 | C17: 79.3881
A18: Ramanathapuram | B18: 9.3716 | C18: 78.8308
A19: Krishnagiri | B19: 12.5266 | C19: 78.2137
A20: Thoothukudi | B20: 8.7642 | C20: 78.1348
A21: Vellore | B21: 12.9165 | C21: 79.1325
A22: Villivakkam | B22: 13.11 | C22: 80.207
A23: Villupuram | B23: 11.9401 | C23: 79.4861
A24: Hosur | B24: 12.7409 | C24: 77.8253
A25: Thanjavur | B25: 10.787 | C25: 79.1378
A26: Coimbatore | B26: 11.0168 | C26: 76.9558
A27: Neelankarai | B27: 12.949 | C27: 80.254
... A45: Tindivanam | B45: 12.2341 | C45: 79.6555
A46: n | B46: FALSE | C46: FALSE
A47: Viluppuram | B47: 11.9401 | C47: 79.4861
A48: Srirangam | B48: 10.862 | C48: 78.6966
A49: Puducherry | B49: 11.9416 | C49: 79.8083
A50: Alandur | B50: 13.004 | C50: 80.201
A51: Perambalur | B51: 11.2342 | C51: 78.8836
A52: Mumbai | B52: 19.076 | C52: 72.8777
A53: Virudhunagar | B53: 9.5851 | C53: 77.9579
A54: Sattur | B54: 9.365 | C54: 77.925
A55: Tamil Nadu | B55: Bengal | C55: FALSE | D55: FALSE
A56: Multiple | B56: FALSE | C56: FALSE
A57: Sankaralingapuram village | B57: 9.5 | C57: 77.8
...
